Workbook

Sheet Backlog
A1: ID | B1: Tool | C1: Cluster | D1: Query (Guide Title) | E1: Slug | F1: Category | G1: Priority | H1: Status | I1: Notes
A2: 1 | B2: DifficultTalkCoach | C2: Upward | D2: How to tell your boss they're wrong | E2: how-to-tell-your-boss-theyre-wrong | F2: workplace | G2: High | H2: Shipped | I2: Anchor guide / exemplar
A3: 2 | B3: DifficultTalkCoach | C3: Upward | D3: How to say no to your boss | E3: how-to-say-no-to-your-boss | F3: workplace | G3: High | H3: Shipped
A4: 3 | B4: DifficultTalkCoach | C4: Upward | D4: How to push back on your boss professionally | E4: how-to-push-back-on-your-boss-professionally | F4: workplace | G4: High | H4: Shipped
A5: 4 | B5: DifficultTalkCoach | C5: Upward | D5: How to tell your boss a deadline is unrealistic | E5: how-to-tell-your-boss-a-deadline-is-unrealistic | F5: workplace | G5: High | H5: Shipped
A6: 5 | B6: DifficultTalkCoach | C6: Upward | D6: How to tell your manager their feedback is unfair | E6: how-to-tell-your-manager-their-feedback-is-unfair | F6: workplace | G6: High | H6: Shipped
A7: 6 | B7: DifficultTalkCoach | C7: Upward | D7: How to ask your boss for a raise | E7: how-to-ask-your-boss-for-a-raise | F7: workplace | G7: High | H7: Candidate | I7: Highest-volume query in this family
A8: 7 | B8: DifficultTalkCoach | C8: Upward | D8: How to tell your boss you're burned out | E8: how-to-tell-your-boss-youre-burned-out | F8: workplace | G8: High | H8: Candidate | I8: Rising trend, emotionally loaded
A9: 8 | B9: DifficultTalkCoach | C9: Upward | D9: How to tell your boss you made a mistake | E9: how-to-tell-your-boss-you-made-a-mistake | F9: workplace | G9: High | H9: Candidate | I9: Classic stakes moment
A10: 9 | B10: DifficultTalkCoach | C10: Upward | D10: How to tell your boss you're quitting | E10: how-to-tell-your-boss-youre-quitting | F10: workplace | G10: High | H10: Candidate | I10: Commercial intent, evergreen
A11: 15 | B11: DifficultTalkCoach | C11: Lateral | D11: How to tell a coworker they're being rude | E11: how-to-tell-a-coworker-theyre-being-rude | F11: workplace | G11: High | H11: Candidate | I11: Classic query
A12: 16 | B12: DifficultTalkCoach | C12: Lateral | D12: How to handle a coworker who takes credit for your work | E12: how-to-handle-a-coworker-who-takes-credit-for-your-work | F12: workplace | G12: High | H12: Candidate | I12: Evergreen, high volume
A13: 17 | B13: DifficultTalkCoach | C13: Lateral | D13: How to respond to a passive aggressive email | E13: how-to-respond-to-a-passive-aggressive-email | F13: workplace | G13: High | H13: Candidate | I13: Directly quoted in audience report
A14: 18 | B14: DifficultTalkCoach | C14: Lateral | D14: How to tell a coworker they smell | E14: how-to-tell-a-coworker-they-smell | F14: workplace | G14: High | H14: Candidate | I14: High volume, real pain
A15: 19 | B15: DifficultTalkCoach | C15: Lateral | D15: How to deal with a coworker who talks too much in meetings | E15: how-to-deal-with-a-coworker-who-talks-too-much-in-meetings | F15: workplace | G15: High | H15: Candidate | I15: Specific, recognizable
A16: 20 | B16: DifficultTalkCoach | C16: Lateral | D16: How to confront a coworker about their behavior | E16: how-to-confront-a-coworker-about-their-behavior | F16: workplace | G16: High | H16: Candidate | I16: Broad umbrella query
A17: 29 | B17: DifficultTalkCoach | C17: Downward | D17: How to give constructive criticism to an employee | E17: how-to-give-constructive-criticism-to-an-employee | F17: workplace | G17: High | H17: Candidate | I17: Evergreen management query
A18: 30 | B18: DifficultTalkCoach | C18: Downward | D18: How to tell an employee their performance is slipping | E18: how-to-tell-an-employee-their-performance-is-slipping | F18: workplace | G18: High | H18: Candidate | I18: Classic moment
... A97: 96 | B97: DifficultTalkCoach | C97: Apology | D97: How to apologize for hurting someone's feelings when you didn't mean to | E97: how-to-apologize-for-hurting-someones-feelings-when-you-didnt-mean-to | F97: conversations | G97: Medium | H97: Candidate | I97: Nuanced
A98: 1 | B98: DoctorVisitPrep | C98: Before | D98: How to prepare for a doctor's appointment | E98: how-to-prepare-for-a-doctors-appointment | F98: health | G98: High | H98: Shipped
A99: 2 | B99: DoctorVisitPrep | C99: Before | D99: What questions to ask your doctor | E99: questions-to-ask-your-doctor | F99: health | G99: High | H99: Shipped
A100: 3 | B100: DoctorVisitPrep | C100: Before | D100: How to describe your symptoms to a doctor | E100: how-to-describe-your-symptoms-to-a-doctor | F100: health | G100: High | H100: Shipped
A101: 7 | B101: DoctorVisitPrep | C101: Before | D101: How to get your concerns taken seriously at the doctor | E101: how-to-get-your-concerns-taken-seriously-at-the-doctor | F101: health | G101: High | H101: Shipped | I101: VOICE: sensitive
A102: 8 | B102: DoctorVisitTranslator | C102: Understand | D102: How to understand what your doctor actually said | E102: how-to-understand-what-your-doctor-actually-said | F102: health | G102: High | H102: Shipped
A103: 13 | B103: DoctorVisitTranslator | C103: Tests | D103: How to read your blood test results | E103: how-to-read-your-blood-test-results | F103: health | G103: High | H103: Candidate
A104: 20 | B104: DoctorVisitPrep | C104: Medication | D104: What to ask before taking a new medication | E104: what-to-ask-before-taking-a-new-medication | F104: health | G104: High | H104: Candidate
A105: 26 | B105: DoctorVisitPrep | C105: Advocacy | D105: How to push back when a doctor isn't listening | E105: how-to-push-back-when-a-doctor-isnt-listening | F105: health | G105: High | H105: Candidate | I105: OVERLAP: DifficultTalkCoach; VOICE: sensitive
A106: 27 | B106: DoctorVisitPrep | C106: Advocacy | D106: How to get a doctor to take your pain seriously | E106: how-to-get-a-doctor-to-take-your-pain-seriously | F106: health | G106: High | H106: Candidate | I106: VOICE: sensitive
A107: 28 | B107: DoctorVisitPrep | C107: Advocacy | D107: How to get a second opinion | E107: how-to-get-a-second-opinion | F107: health | G107: High | H107: Candidate
A108: 30 | B108: DoctorVisitPrep | C108: Advocacy | D108: How to advocate for yourself at the doctor | E108: how-to-advocate-for-yourself-at-the-doctor | F108: health | G108: High | H108: Candidate
A109: 37 | B109: DoctorVisitTranslator | C109: Diagnosis | D109: How to understand a cancer diagnosis | E109: how-to-understand-a-cancer-diagnosis | F109: health | G109: High | H109: Candidate | I109: VOICE: full empathy register. No dry humor.
A110: 6 | B110: DoctorVisitPrep | C110: Before | D110: What to bring to a doctor's appointment | E110: what-to-bring-to-a-doctors-appointment | F110: health | G110: Low | H110: Candidate
A111: 12 | B111: DoctorVisitPrep | C111: Understand | D111: How to take notes during a doctor's appointment | E111: how-to-take-notes-during-a-doctors-appointment | F111: health | G111: Low | H111: Candidate
A112: 25 | B112: DoctorVisitTranslator | C112: Medication | D112: How to read a prescription label | E112: how-to-read-a-prescription-label | F112: health | G112: Low | H112: Candidate
A113: 4 | B113: DoctorVisitPrep | C113: Before | D113: How to make the most of a 15-minute doctor visit | E113: how-to-make-the-most-of-a-15-minute-doctor-visit | F113: health | G113: Medium | H113: Candidate
A114: 5 | B114: DoctorVisitPrep | C114: Before | D114: How to prepare for a first appointment with a new doctor | E114: how-to-prepare-for-a-first-appointment-with-a-new-doctor | F114: health | G114: Medium | H114: Candidate
A115: 9 | B115: DoctorVisitPrep | C115: Understand | D115: How to ask a doctor to explain something | E115: how-to-ask-a-doctor-to-explain-something | F115: health | G115: Medium | H115: Candidate
A116: 10 | B116: DoctorVisitTranslator | C116: Understand | D116: How to understand medical jargon | E116: how-to-understand-medical-jargon | F116: health | G116: Medium | H116: Candidate
A117: 11 | B117: DoctorVisitTranslator | C117: Understand | D117: How to translate a doctor's note into plain language | E117: how-to-translate-a-doctors-note-into-plain-language | F117: health | G117: Medium | H117: Candidate
A118: 14 | B118: DoctorVisitTranslator | C118: Tests | D118: What does abnormal mean on a blood test | E118: what-does-abnormal-mean-on-a-blood-test | F118: health | G118: Medium | H118: Candidate
...

Sheet Summary
A1: Tool | B1: Cluster | C1: Total Queries | D1: Shipped | E1: Candidates | F1: High Priority (remaining)
A2: DifficultTalkCoach | B2: Upward | C2: =COUNTIFS(Backlog!B:B,"DifficultTalkCoach",Backlog!C:C,"Upward") -> 14 | D2: =COUNTIFS(Backlog!B:B,"DifficultTalkCoach",Backlog!C:C,"Upward",Backlog!H:H,"Shipped") -> 5 | E2: =COUNTIFS(Backlog!B:B,"DifficultTalkCoach",Backlog!C:C,"Upward",Backlog!H:H,"Candidate") -> 9 | F2: =COUNTIFS(Backlog!B:B,"DifficultTalkCoach",Backlog!C:C,"Upward",Backlog!G:G,"High",Backlog!H:H,"Candidate") -> 4
A3: DifficultTalkCoach | B3: Lateral | C3: =COUNTIFS(Backlog!B:B,"DifficultTalkCoach",Backlog!C:C,"Lateral") -> 14 | D3: =COUNTIFS(Backlog!B:B,"DifficultTalkCoach",Backlog!C:C,"Lateral",Backlog!H:H,"Shipped") -> 0 | E3: =COUNTIFS(Backlog!B:B,"DifficultTalkCoach",Backlog!C:C,"Lateral",Backlog!H:H,"Candidate") -> 14 | F3: =COUNTIFS(Backlog!B:B,"DifficultTalkCoach",Backlog!C:C,"Lateral",Backlog!G:G,"High",Backlog!H:H,"Candidate") -> 6
A4: DifficultTalkCoach | B4: Downward | C4: =COUNTIFS(Backlog!B:B,"DifficultTalkCoach",Backlog!C:C,"Downward") -> 10 | D4: =COUNTIFS(Backlog!B:B,"DifficultTalkCoach",Backlog!C:C,"Downward",Backlog!H:H,"Shipped") -> 0 | E4: =COUNTIFS(Backlog!B:B,"DifficultTalkCoach",Backlog!C:C,"Downward",Backlog!H:H,"Candidate") -> 10 | F4: =COUNTIFS(Backlog!B:B,"DifficultTalkCoach",Backlog!C:C,"Downward",Backlog!G:G,"High",Backlog!H:H,"Candidate") -> 4
A5: DifficultTalkCoach | B5: Partner | C5: =COUNTIFS(Backlog!B:B,"DifficultTalkCoach",Backlog!C:C,"Partner") -> 13 | D5: =COUNTIFS(Backlog!B:B,"DifficultTalkCoach",Backlog!C:C,"Partner",Backlog!H:H,"Shipped") -> 0 | E5: =COUNTIFS(Backlog!B:B,"DifficultTalkCoach",Backlog!C:C,"Partner",Backlog!H:H,"Candidate") -> 13 | F5: =COUNTIFS(Backlog!B:B,"DifficultTalkCoach",Backlog!C:C,"Partner",Backlog!G:G,"High",Backlog!H:H,"Candidate") -> 5
A6: DifficultTalkCoach | B6: Family | C6: =COUNTIFS(Backlog!B:B,"DifficultTalkCoach",Backlog!C:C,"Family") -> 12 | D6: =COUNTIFS(Backlog!B:B,"DifficultTalkCoach",Backlog!C:C,"Family",Backlog!H:H,"Shipped") -> 0 | E6: =COUNTIFS(Backlog!B:B,"DifficultTalkCoach",Backlog!C:C,"Family",Backlog!H:H,"Candidate") -> 12 | F6: =COUNTIFS(Backlog!B:B,"DifficultTalkCoach",Backlog!C:C,"Family",Backlog!G:G,"High",Backlog!H:H,"Candidate") -> 4
A7: DifficultTalkCoach | B7: Friends | C7: =COUNTIFS(Backlog!B:B,"DifficultTalkCoach",Backlog!C:C,"Friends") -> 9 | D7: =COUNTIFS(Backlog!B:B,"DifficultTalkCoach",Backlog!C:C,"Friends",Backlog!H:H,"Shipped") -> 0 | E7: =COUNTIFS(Backlog!B:B,"DifficultTalkCoach",Backlog!C:C,"Friends",Backlog!H:H,"Candidate") -> 9 | F7: =COUNTIFS(Backlog!B:B,"DifficultTalkCoach",Backlog!C:C,"Friends",Backlog!G:G,"High",Backlog!H:H,"Candidate") -> 4
A8: DifficultTalkCoach | B8: Hard news | C8: =COUNTIFS(Backlog!B:B,"DifficultTalkCoach",Backlog!C:C,"Hard news") -> 6 | D8: =COUNTIFS(Backlog!B:B,"DifficultTalkCoach",Backlog!C:C,"Hard news",Backlog!H:H,"Shipped") -> 0 | E8: =COUNTIFS(Backlog!B:B,"DifficultTalkCoach",Backlog!C:C,"Hard news",Backlog!H:H,"Candidate") -> 6 | F8: =COUNTIFS(Backlog!B:B,"DifficultTalkCoach",Backlog!C:C,"Hard news",Backlog!G:G,"High",Backlog!H:H,"Candidate") -> 3
A9: DifficultTalkCoach | B9: Asking | C9: =COUNTIFS(Backlog!B:B,"DifficultTalkCoach",Backlog!C:C,"Asking") -> 7 | D9: =COUNTIFS(Backlog!B:B,"DifficultTalkCoach",Backlog!C:C,"Asking",Backlog!H:H,"Shipped") -> 0 | E9: =COUNTIFS(Backlog!B:B,"DifficultTalkCoach",Backlog!C:C,"Asking",Backlog!H:H,"Candidate") -> 7 | F9: =COUNTIFS(Backlog!B:B,"DifficultTalkCoach",Backlog!C:C,"Asking",Backlog!G:G,"High",Backlog!H:H,"Candidate") -> 4
A10: DifficultTalkCoach | B10: Saying no | C10: =COUNTIFS(Backlog!B:B,"DifficultTalkCoach",Backlog!C:C,"Saying no") -> 6 | D10: =COUNTIFS(Backlog!B:B,"DifficultTalkCoach",Backlog!C:C,"Saying no",Backlog!H:H,"Shipped") -> 0 | E10: =COUNTIFS(Backlog!B:B,"DifficultTalkCoach",Backlog!C:C,"Saying no",Backlog!H:H,"Candidate") -> 6 | F10: =COUNTIFS(Backlog!B:B,"DifficultTalkCoach",Backlog!C:C,"Saying no",Backlog!G:G,"High",Backlog!H:H,"Candidate") -> 3
A11: DifficultTalkCoach | B11: Apology | C11: =COUNTIFS(Backlog!B:B,"DifficultTalkCoach",Backlog!C:C,"Apology") -> 5 | D11: =COUNTIFS(Backlog!B:B,"DifficultTalkCoach",Backlog!C:C,"Apology",Backlog!H:H,"Shipped") -> 0 | E11: =COUNTIFS(Backlog!B:B,"DifficultTalkCoach",Backlog!C:C,"Apology",Backlog!H:H,"Candidate") -> 5 | F11: =COUNTIFS(Backlog!B:B,"DifficultTalkCoach",Backlog!C:C,"Apology",Backlog!G:G,"High",Backlog!H:H,"Candidate") -> 1
A12: UpsellShield | B12: Cars | C12: =COUNTIFS(Backlog!B:B,"UpsellShield",Backlog!C:C,"Cars") -> 9 | D12: =COUNTIFS(Backlog!B:B,"UpsellShield",Backlog!C:C,"Cars",Backlog!H:H,"Shipped") -> 0 | E12: =COUNTIFS(Backlog!B:B,"UpsellShield",Backlog!C:C,"Cars",Backlog!H:H,"Candidate") -> 9 | F12: =COUNTIFS(Backlog!B:B,"UpsellShield",Backlog!C:C,"Cars",Backlog!G:G,"High",Backlog!H:H,"Candidate") -> 5
A13: UpsellShield | B13: Subscriptions | C13: =COUNTIFS(Backlog!B:B,"UpsellShield",Backlog!C:C,"Subscriptions") -> 8 | D13: =COUNTIFS(Backlog!B:B,"UpsellShield",Backlog!C:C,"Subscriptions",Backlog!H:H,"Shipped") -> 0 | E13: =COUNTIFS(Backlog!B:B,"UpsellShield",Backlog!C:C,"Subscriptions",Backlog!H:H,"Candidate") -> 8 | F13: =COUNTIFS(Backlog!B:B,"UpsellShield",Backlog!C:C,"Subscriptions",Backlog!G:G,"High",Backlog!H:H,"Candidate") -> 5
A14: UpsellShield | B14: Services | C14: =COUNTIFS(Backlog!B:B,"UpsellShield",Backlog!C:C,"Services") -> 5 | D14: =COUNTIFS(Backlog!B:B,"UpsellShield",Backlog!C:C,"Services",Backlog!H:H,"Shipped") -> 0 | E14: =COUNTIFS(Backlog!B:B,"UpsellShield",Backlog!C:C,"Services",Backlog!H:H,"Candidate") -> 5 | F14: =COUNTIFS(Backlog!B:B,"UpsellShield",Backlog!C:C,"Services",Backlog!G:G,"High",Backlog!H:H,"Candidate") -> 1
A15: UpsellShield | B15: Pressure | C15: =COUNTIFS(Backlog!B:B,"UpsellShield",Backlog!C:C,"Pressure") -> 10 | D15: =COUNTIFS(Backlog!B:B,"UpsellShield",Backlog!C:C,"Pressure",Backlog!H:H,"Shipped") -> 0 | E15: =COUNTIFS(Backlog!B:B,"UpsellShield",Backlog!C:C,"Pressure",Backlog!H:H,"Candidate") -> 10 | F15: =COUNTIFS(Backlog!B:B,"UpsellShield",Backlog!C:C,"Pressure",Backlog!G:G,"High",Backlog!H:H,"Candidate") -> 4
A16: UpsellShield | B16: Dark patterns | C16: =COUNTIFS(Backlog!B:B,"UpsellShield",Backlog!C:C,"Dark patterns") -> 5 | D16: =COUNTIFS(Backlog!B:B,"UpsellShield",Backlog!C:C,"Dark patterns",Backlog!H:H,"Shipped") -> 0 | E16: =COUNTIFS(Backlog!B:B,"UpsellShield",Backlog!C:C,"Dark patterns",Backlog!H:H,"Candidate") -> 5 | F16: =COUNTIFS(Backlog!B:B,"UpsellShield",Backlog!C:C,"Dark patterns",Backlog!G:G,"High",Backlog!H:H,"Candidate") -> 1
A17: UpsellShield | B17: Financial | C17: =COUNTIFS(Backlog!B:B,"UpsellShield",Backlog!C:C,"Financial") -> 8 | D17: =COUNTIFS(Backlog!B:B,"UpsellShield",Backlog!C:C,"Financial",Backlog!H:H,"Shipped") -> 0 | E17: =COUNTIFS(Backlog!B:B,"UpsellShield",Backlog!C:C,"Financial",Backlog!H:H,"Candidate") -> 8 | F17: =COUNTIFS(Backlog!B:B,"UpsellShield",Backlog!C:C,"Financial",Backlog!G:G,"High",Backlog!H:H,"Candidate") -> 4
A18: UpsellShield | B18: Tactics | C18: =COUNTIFS(Backlog!B:B,"UpsellShield",Backlog!C:C,"Tactics") -> 7 | D18: =COUNTIFS(Backlog!B:B,"UpsellShield",Backlog!C:C,"Tactics",Backlog!H:H,"Shipped") -> 0 | E18: =COUNTIFS(Backlog!B:B,"UpsellShield",Backlog!C:C,"Tactics",Backlog!H:H,"Candidate") -> 7 | F18: =COUNTIFS(Backlog!B:B,"UpsellShield",Backlog!C:C,"Tactics",Backlog!G:G,"High",Backlog!H:H,"Candidate") -> 3
A19: UpsellShield | B19: Recovery | C19: =COUNTIFS(Backlog!B:B,"UpsellShield",Backlog!C:C,"Recovery") -> 5 | D19: =COUNTIFS(Backlog!B:B,"UpsellShield",Backlog!C:C,"Recovery",Backlog!H:H,"Shipped") -> 0 | E19: =COUNTIFS(Backlog!B:B,"UpsellShield",Backlog!C:C,"Recovery",Backlog!H:H,"Candidate") -> 5 | F19: =COUNTIFS(Backlog!B:B,"UpsellShield",Backlog!C:C,"Recovery",Backlog!G:G,"High",Backlog!H:H,"Candidate") -> 2
A20: LeaseTrapDetector | B20: Pre-signing | C20: =COUNTIFS(Backlog!B:B,"LeaseTrapDetector",Backlog!C:C,"Pre-signing") -> 7 | D20: =COUNTIFS(Backlog!B:B,"LeaseTrapDetector",Backlog!C:C,"Pre-signing",Backlog!H:H,"Shipped") -> 0 | E20: =COUNTIFS(Backlog!B:B,"LeaseTrapDetector",Backlog!C:C,"Pre-signing",Backlog!H:H,"Candidate") -> 7 | F20: =COUNTIFS(Backlog!B:B,"LeaseTrapDetector",Backlog!C:C,"Pre-signing",Backlog!G:G,"High",Backlog!H:H,"Candidate") -> 4
A21: LeaseTrapDetector | B21: Clauses | C21: =COUNTIFS(Backlog!B:B,"LeaseTrapDetector",Backlog!C:C,"Clauses") -> 7 | D21: =COUNTIFS(Backlog!B:B,"LeaseTrapDetector",Backlog!C:C,"Clauses",Backlog!H:H,"Shipped") -> 0 | E21: =COUNTIFS(Backlog!B:B,"LeaseTrapDetector",Backlog!C:C,"Clauses",Backlog!H:H,"Candidate") -> 7 | F21: =COUNTIFS(Backlog!B:B,"LeaseTrapDetector",Backlog!C:C,"Clauses",Backlog!G:G,"High",Backlog!H:H,"Candidate") -> 1
A22: LeaseTrapDetector | B22: Negotiation | C22: =COUNTIFS(Backlog!B:B,"LeaseTrapDetector",Backlog!C:C,"Negotiation") -> 6 | D22: =COUNTIFS(Backlog!B:B,"LeaseTrapDetector",Backlog!C:C,"Negotiation",Backlog!H:H,"Shipped") -> 0 | E22: =COUNTIFS(Backlog!B:B,"LeaseTrapDetector",Backlog!C:C,"Negotiation",Backlog!H:H,"Candidate") -> 6 | F22: =COUNTIFS(Backlog!B:B,"LeaseTrapDetector",Backlog!C:C,"Negotiation",Backlog!G:G,"High",Backlog!H:H,"Candidate") -> 1
A23: LeaseTrapDetector | B23: Landlord limits | C23: =COUNTIFS(Backlog!B:B,"LeaseTrapDetector",Backlog!C:C,"Landlord limits") -> 7 | D23: =COUNTIFS(Backlog!B:B,"LeaseTrapDetector",Backlog!C:C,"Landlord limits",Backlog!H:H,"Shipped") -> 0 | E23: =COUNTIFS(Backlog!B:B,"LeaseTrapDetector",Backlog!C:C,"Landlord limits",Backlog!H:H,"Candidate") -> 7 | F23: =COUNTIFS(Backlog!B:B,"LeaseTrapDetector",Backlog!C:C,"Landlord limits",Backlog!G:G,"High",Backlog!H:H,"Candidate") -> 3
A24: LeaseTrapDetector | B24: Post-signing | C24: =COUNTIFS(Backlog!B:B,"LeaseTrapDetector",Backlog!C:C,"Post-signing") -> 5 | D24: =COUNTIFS(Backlog!B:B,"LeaseTrapDetector",Backlog!C:C,"Post-signing",Backlog!H:H,"Shipped") -> 0 | E24: =COUNTIFS(Backlog!B:B,"LeaseTrapDetector",Backlog!C:C,"Post-signing",Backlog!H:H,"Candidate") -> 5 | F24: =COUNTIFS(Backlog!B:B,"LeaseTrapDetector",Backlog!C:C,"Post-signing",Backlog!G:G,"High",Backlog!H:H,"Candidate") -> 2
A25: LeaseTrapDetector | B25: Vetting | C25: =COUNTIFS(Backlog!B:B,"LeaseTrapDetector",Backlog!C:C,"Vetting") -> 3 | D25: =COUNTIFS(Backlog!B:B,"LeaseTrapDetector",Backlog!C:C,"Vetting",Backlog!H:H,"Shipped") -> 0 | E25: =COUNTIFS(Backlog!B:B,"LeaseTrapDetector",Backlog!C:C,"Vetting",Backlog!H:H,"Candidate") -> 3 | F25: =COUNTIFS(Backlog!B:B,"LeaseTrapDetector",Backlog!C:C,"Vetting",Backlog!G:G,"High",Backlog!H:H,"Candidate") -> 0
A26: LeaseTrapDetector | B26: Special | C26: =COUNTIFS(Backlog!B:B,"LeaseTrapDetector",Backlog!C:C,"Special") -> 3 | D26: =COUNTIFS(Backlog!B:B,"LeaseTrapDetector",Backlog!C:C,"Special",Backlog!H:H,"Shipped") -> 0 | E26: =COUNTIFS(Backlog!B:B,"LeaseTrapDetector",Backlog!C:C,"Special",Backlog!H:H,"Candidate") -> 3 | F26: =COUNTIFS(Backlog!B:B,"LeaseTrapDetector",Backlog!C:C,"Special",Backlog!G:G,"High",Backlog!H:H,"Candidate") -> 0
A27: DoctorVisitTranslator | B27: Before | C27: =COUNTIFS(Backlog!B:B,"DoctorVisitTranslator",Backlog!C:C,"Before") -> 0 | D27: =COUNTIFS(Backlog!B:B,"DoctorVisitTranslator",Backlog!C:C,"Before",Backlog!H:H,"Shipped") -> 0 | E27: =COUNTIFS(Backlog!B:B,"DoctorVisitTranslator",Backlog!C:C,"Before",Backlog!H:H,"Candidate") -> 0 | F27: =COUNTIFS(Backlog!B:B,"DoctorVisitTranslator",Backlog!C:C,"Before",Backlog!G:G,"High",Backlog!H:H,"Candidate") -> 0
A28: DoctorVisitTranslator | B28: Understand | C28: =COUNTIFS(Backlog!B:B,"DoctorVisitTranslator",Backlog!C:C,"Understand") -> 3 | D28: =COUNTIFS(Backlog!B:B,"DoctorVisitTranslator",Backlog!C:C,"Understand",Backlog!H:H,"Shipped") -> 1 | E28: =COUNTIFS(Backlog!B:B,"DoctorVisitTranslator",Backlog!C:C,"Understand",Backlog!H:H,"Candidate") -> 2 | F28: =COUNTIFS(Backlog!B:B,"DoctorVisitTranslator",Backlog!C:C,"Understand",Backlog!G:G,"High",Backlog!H:H,"Candidate") -> 0
A29: DoctorVisitTranslator | B29: Tests | C29: =COUNTIFS(Backlog!B:B,"DoctorVisitTranslator",Backlog!C:C,"Tests") -> 7 | D29: =COUNTIFS(Backlog!B:B,"DoctorVisitTranslator",Backlog!C:C,"Tests",Backlog!H:H,"Shipped") -> 0 | E29: =COUNTIFS(Backlog!B:B,"DoctorVisitTranslator",Backlog!C:C,"Tests",Backlog!H:H,"Candidate") -> 7 | F29: =COUNTIFS(Backlog!B:B,"DoctorVisitTranslator",Backlog!C:C,"Tests",Backlog!G:G,"High",Backlog!H:H,"Candidate") -> 1
A30: DoctorVisitTranslator | B30: Medication | C30: =COUNTIFS(Backlog!B:B,"DoctorVisitTranslator",Backlog!C:C,"Medication") -> 3 | D30: =COUNTIFS(Backlog!B:B,"DoctorVisitTranslator",Backlog!C:C,"Medication",Backlog!H:H,"Shipped") -> 0 | E30: =COUNTIFS(Backlog!B:B,"DoctorVisitTranslator",Backlog!C:C,"Medication",Backlog!H:H,"Candidate") -> 3 | F30: =COUNTIFS(Backlog!B:B,"DoctorVisitTranslator",Backlog!C:C,"Medication",Backlog!G:G,"High",Backlog!H:H,"Candidate") -> 0
A31: DoctorVisitTranslator | B31: Advocacy | C31: =COUNTIFS(Backlog!B:B,"DoctorVisitTranslator",Backlog!C:C,"Advocacy") -> 0 | D31: =COUNTIFS(Backlog!B:B,"DoctorVisitTranslator",Backlog!C:C,"Advocacy",Backlog!H:H,"Shipped") -> 0 | E31: =COUNTIFS(Backlog!B:B,"DoctorVisitTranslator",Backlog!C:C,"Advocacy",Backlog!H:H,"Candidate") -> 0 | F31: =COUNTIFS(Backlog!B:B,"DoctorVisitTranslator",Backlog!C:C,"Advocacy",Backlog!G:G,"High",Backlog!H:H,"Candidate") -> 0
A32: DoctorVisitTranslator | B32: Specialists | C32: =COUNTIFS(Backlog!B:B,"DoctorVisitTranslator",Backlog!C:C,"Specialists") -> 1 | D32: =COUNTIFS(Backlog!B:B,"DoctorVisitTranslator",Backlog!C:C,"Specialists",Backlog!H:H,"Shipped") -> 0 | E32: =COUNTIFS(Backlog!B:B,"DoctorVisitTranslator",Backlog!C:C,"Specialists",Backlog!H:H,"Candidate") -> 1 | F32: =COUNTIFS(Backlog!B:B,"DoctorVisitTranslator",Backlog!C:C,"Specialists",Backlog!G:G,"High",Backlog!H:H,"Candidate") -> 0
A33: DoctorVisitTranslator | B33: Diagnosis | C33: =COUNTIFS(Backlog!B:B,"DoctorVisitTranslator",Backlog!C:C,"Diagnosis") -> 3 | D33: =COUNTIFS(Backlog!B:B,"DoctorVisitTranslator",Backlog!C:C,"Diagnosis",Backlog!H:H,"Shipped") -> 0 | E33: =COUNTIFS(Backlog!B:B,"DoctorVisitTranslator",Backlog!C:C,"Diagnosis",Backlog!H:H,"Candidate") -> 3 | F33: =COUNTIFS(Backlog!B:B,"DoctorVisitTranslator",Backlog!C:C,"Diagnosis",Backlog!G:G,"High",Backlog!H:H,"Candidate") -> 1
A34: DoctorVisitPrep | B34: Before | C34: =COUNTIFS(Backlog!B:B,"DoctorVisitPrep",Backlog!C:C,"Before") -> 7 | D34: =COUNTIFS(Backlog!B:B,"DoctorVisitPrep",Backlog!C:C,"Before",Backlog!H:H,"Shipped") -> 4 | E34: =COUNTIFS(Backlog!B:B,"DoctorVisitPrep",Backlog!C:C,"Before",Backlog!H:H,"Candidate") -> 3 | F34: =COUNTIFS(Backlog!B:B,"DoctorVisitPrep",Backlog!C:C,"Before",Backlog!G:G,"High",Backlog!H:H,"Candidate") -> 0
A35: DoctorVisitPrep | B35: Understand | C35: =COUNTIFS(Backlog!B:B,"DoctorVisitPrep",Backlog!C:C,"Understand") -> 2 | D35: =COUNTIFS(Backlog!B:B,"DoctorVisitPrep",Backlog!C:C,"Understand",Backlog!H:H,"Shipped") -> 0 | E35: =COUNTIFS(Backlog!B:B,"DoctorVisitPrep",Backlog!C:C,"Understand",Backlog!H:H,"Candidate") -> 2 | F35: =COUNTIFS(Backlog!B:B,"DoctorVisitPrep",Backlog!C:C,"Understand",Backlog!G:G,"High",Backlog!H:H,"Candidate") -> 0
A36: DoctorVisitPrep | B36: Medication | C36: =COUNTIFS(Backlog!B:B,"DoctorVisitPrep",Backlog!C:C,"Medication") -> 3 | D36: =COUNTIFS(Backlog!B:B,"DoctorVisitPrep",Backlog!C:C,"Medication",Backlog!H:H,"Shipped") -> 0 | E36: =COUNTIFS(Backlog!B:B,"DoctorVisitPrep",Backlog!C:C,"Medication",Backlog!H:H,"Candidate") -> 3 | F36: =COUNTIFS(Backlog!B:B,"DoctorVisitPrep",Backlog!C:C,"Medication",Backlog!G:G,"High",Backlog!H:H,"Candidate") -> 1
A37: DoctorVisitPrep | B37: Advocacy | C37: =COUNTIFS(Backlog!B:B,"DoctorVisitPrep",Backlog!C:C,"Advocacy") -> 8 | D37: =COUNTIFS(Backlog!B:B,"DoctorVisitPrep",Backlog!C:C,"Advocacy",Backlog!H:H,"Shipped") -> 0 | E37: =COUNTIFS(Backlog!B:B,"DoctorVisitPrep",Backlog!C:C,"Advocacy",Backlog!H:H,"Candidate") -> 8 | F37: =COUNTIFS(Backlog!B:B,"DoctorVisitPrep",Backlog!C:C,"Advocacy",Backlog!G:G,"High",Backlog!H:H,"Candidate") -> 4
A38: DoctorVisitPrep | B38: Specialists | C38: =COUNTIFS(Backlog!B:B,"DoctorVisitPrep",Backlog!C:C,"Specialists") -> 2 | D38: =COUNTIFS(Backlog!B:B,"DoctorVisitPrep",Backlog!C:C,"Specialists",Backlog!H:H,"Shipped") -> 0 | E38: =COUNTIFS(Backlog!B:B,"DoctorVisitPrep",Backlog!C:C,"Specialists",Backlog!H:H,"Candidate") -> 2 | F38: =COUNTIFS(Backlog!B:B,"DoctorVisitPrep",Backlog!C:C,"Specialists",Backlog!G:G,"High",Backlog!H:H,"Candidate") -> 0
A39: DoctorVisitPrep | B39: Diagnosis | C39: =COUNTIFS(Backlog!B:B,"DoctorVisitPrep",Backlog!C:C,"Diagnosis") -> 1 | D39: =COUNTIFS(Backlog!B:B,"DoctorVisitPrep",Backlog!C:C,"Diagnosis",Backlog!H:H,"Shipped") -> 0 | E39: =COUNTIFS(Backlog!B:B,"DoctorVisitPrep",Backlog!C:C,"Diagnosis",Backlog!H:H,"Candidate") -> 1 | F39: =COUNTIFS(Backlog!B:B,"DoctorVisitPrep",Backlog!C:C,"Diagnosis",Backlog!G:G,"High",Backlog!H:H,"Candidate") -> 0
A40: TOTAL | C40: =SUM(C2:C39) -> 231 | D40: =SUM(D2:D39) -> 10 | E40: =SUM(E2:E39) -> 221 | F40: =SUM(F2:F39) -> 81

Sheet Tool Fitness
A1: Tool | B1: Tagline | C1: SEO Fit | D1: Est. Queries | E1: Status | F1: Notes | H1: Totals | I1: Tools | J1: Est. Queries
A2: DifficultTalkCoach | B2: Practice hard conversations before they happen | C2: HIGH | D2: 96 | E2: Done | F2: Shipped: 5 guides | H2: HIGH | I2: =COUNTIF(C:C,"HIGH") -> 16 | J2: =SUMIF(C:C,"HIGH",D:D) -> 464
A3: UpsellShield | B3: Walk into high-pressure sales prepared | C3: HIGH | D3: 57 | E3: Done | F3: Discovered; subscription cluster may reassign to SubscriptionGuiltTrip | H3: MEDIUM | I3: =COUNTIF(C:C,"MEDIUM") -> 35 | J3: =SUMIF(C:C,"MEDIUM",D:D) -> 336
A4: DoctorVisitTranslator | B4: Turn medical jargon into plain English | C4: HIGH | D4: 17 | E4: Done | F4: Owns translation/comprehension of results — what the doctor said, medical jargon, test and imaging reports, medication side effects, diagnoses. All asking and prep-for-discussion goes to DoctorVisitPrep. | H4: LOW | I4: =COUNTIF(C:C,"LOW") -> 40 | J4: =SUMIF(C:C,"LOW",D:D) -> 131
A5: DoctorVisitPrep | B5: TBD — confirm with deployed copy | C5: HIGH | D5: 23 | E5: Done | F5: Owns preparation for the discussion — visit prep, advocacy strategy, how-to-ask, how-to-talk-to. Split off from DVT this session. | H5: NONE | I5: =COUNTIF(C:C,"NONE") -> 28 | J5: =SUMIF(C:C,"NONE",D:D) -> 0
A6: LeaseTrapDetector | B6: Find predatory clauses hiding in your lease | C6: HIGH | D6: 38 | E6: Done | F6: Discovered | H6: TOTAL | I6: =SUM(I2:I5) -> 119 | J6: =SUM(J2:J5) -> 931
A7: PetWeirdnessDecoder | B7: Is it quirky or concerning? | C7: HIGH | D7: 30 | E7: Queue | F7: Huge cluster: 'why is my cat/dog X' queries
A8: PlantRescue | B8: Why are my leaves turning yellow? | C8: HIGH | D8: 30 | E8: Queue | F8: Huge cluster: 'why is my plant X' queries
A9: BikeMedic | B9: A trailside mechanic in your pocket | C9: HIGH | D9: 25 | E9: Queue | F9: 'How to fix a bike X' cluster — technical repair
A10: ConflictCoach | B10: Stop, breathe, and craft the right response | C10: HIGH | D10: 25 | E10: Triage | F10: Heavy DTC overlap — triage which tool owns which queries
A11: ComplaintEscalationWriter | B11: Full escalation campaigns companies can't ignore | C11: HIGH | D11: 20 | E11: Queue | F11: 'How to file/escalate complaint against X' cluster
A12: MarkupDetective | B12: Why does this cost that? Follow the money | C12: HIGH | D12: 20 | E12: Queue | F12: Overdue: UpsellShield flagged 4 overlap queries
A13: RulebookBreaker | B13: Loopholes, magic words, escalation ladder | C13: HIGH | D13: 20 | E13: Queue | F13: Overlaps UpsellShield/ComplaintEscalationWriter
A14: BillRescue | B14: Your bill anxiety ends here | C14: HIGH | D14: 18 | E14: Queue | F14: 'How to dispute/negotiate/read a bill' — overlaps MarkupDetective
A15: RentersDepositSaver | B15: Protect your security deposit on move-in day | C15: HIGH | D15: 15 | E15: Queue | F15: Distinct from LeaseTrapDetector (move-in moment)
A16: SubscriptionGuiltTrip | B16: Cancel what you don't use. Negotiate what you keep | C16: HIGH | D16: 15 | E16: Triage | F16: REASSIGN: UpsellShield Subscriptions cluster likely belongs here
A17: ToastWriter | B17: Toasts, speeches, and tributes that land | C17: HIGH | D17: 15 | E17: Queue | F17: Wedding/funeral toast queries are high-volume, high-intent
A18: Giftology | B18: The perfect gift for the hardest person to shop for | C18: MEDIUM | D18: 15 | E18: Queue | F18: 'Gift ideas for X' — huge volume but very competitive
... A120: WrongAnswersOnly | B120: Get a confidently, beautifully wrong answer | C120: NONE | D120: 0 | E120: Skip | F120: Humor

Sheet Legend
A1: DeftBrain Guide Backlog — Legend
A3: Columns
A4: ID | B4: Sequential within the tool. For reference; not a URL.
A5: Tool | B5: Which DeftBrain tool the guide CTAs to.
A6: Cluster | B6: Query-space cluster within this tool. Used for writing rhythm.
A7: Query (Guide Title) | B7: The actual phrase someone would Google. The guide ranks for this.
A8: Slug | B8: URL slug. Lowercase, hyphenated, apostrophes removed. Auto-derived from query.
A9: Category | B9: Top-level section on deftbrain.com/guides. Current: workplace, conversations.
A10: Priority | B10: High / Medium / Low — by likely volume × intent × competitive fit.
A11: Status | B11: Candidate (not yet written) / Drafting / Shipped.
A12: Notes | B12: Context, overlaps with other tools, voice flags, etc.
A14: Priority color coding
A15: High | B15: Soft amber — the queries to write first.
A16: Medium | B16: Soft yellow — second-wave candidates.
A17: Low | B17: Soft green — write only when cluster is nearly saturated.
A19: Voice flags
A20: Hard news cluster | B20: Standard voice rules do NOT apply. No dry humor. Full empathy register. When writing these, consider a modified voice spec.
A21: Overlap notes | B21: Some queries plausibly serve multiple tools. Triage is deferred until every tool has its own discovery pass. Marked 'OVERLAP' in Notes.
A23: Workflow
A24: 1 | B24: A tool's discovery pass adds its queries to the Backlog sheet.
A25: 2 | B25: Priorities and category assignments get reviewed.
A26: 3 | B26: Candidates are drafted (style guide + existing specs as reference).
A27: 4 | B27: Status moves to Shipped when the guide is live.
A28: 5 | B28: Summary sheet auto-updates from the Backlog via COUNTIFS formulas.
A30: Categories used
A31: workplace | B31: Work/manager/coworker/team communication (existing).
A32: conversations | B32: Personal conversations — partner, family, friends, hard news (new, introduced with DifficultTalkCoach pass).
A33: consumer | B33: Buying, selling, negotiating, subscriptions, consumer defense (new, introduced with UpsellShield pass).
A34: home | B34: Housing, rentals, leases, home ownership, household admin (introduced with LeaseTrapDetector pass).
A35: health | B35: Patient-doctor communication, medical literacy, test results, medication, serious diagnoses (introduced with DoctorVisitTranslator pass; expanded with DoctorVisitPrep for visit-prep and advocacy strategy).
